[2024-09-22T16:26:51.310+0000] {local_task_job_runner.py:123} INFO - ::group::Pre task execution logs
[2024-09-22T16:26:51.320+0000] {taskinstance.py:2612} INFO - Dependencies all met for dep_context=non-requeueable deps ti=<TaskInstance: project.store_user manual__2024-09-22T15:42:00.765595+00:00 [queued]>
[2024-09-22T16:26:51.326+0000] {taskinstance.py:2612} INFO - Dependencies all met for dep_context=requeueable deps ti=<TaskInstance: project.store_user manual__2024-09-22T15:42:00.765595+00:00 [queued]>
[2024-09-22T16:26:51.327+0000] {taskinstance.py:2865} INFO - Starting attempt 4 of 4
[2024-09-22T16:26:51.337+0000] {taskinstance.py:2888} INFO - Executing <Task(PythonOperator): store_user> on 2024-09-22 15:42:00.765595+00:00
[2024-09-22T16:26:51.344+0000] {standard_task_runner.py:104} INFO - Running: ['***', 'tasks', 'run', 'project', 'store_user', 'manual__2024-09-22T15:42:00.765595+00:00', '--job-id', '78', '--raw', '--subdir', 'DAGS_FOLDER/project.py', '--cfg-path', '/tmp/tmp0ws5f2t9']
[2024-09-22T16:26:51.345+0000] {warnings.py:112} WARNING - /home/***/.local/lib/python3.12/site-packages/***/task/task_runner/standard_task_runner.py:70: DeprecationWarning: This process (pid=8386) is multi-threaded, use of fork() may lead to deadlocks in the child.
  pid = os.fork()

[2024-09-22T16:26:51.345+0000] {standard_task_runner.py:105} INFO - Job 78: Subtask store_user
[2024-09-22T16:26:51.345+0000] {standard_task_runner.py:72} INFO - Started process 8388 to run task
[2024-09-22T16:26:51.382+0000] {task_command.py:467} INFO - Running <TaskInstance: project.store_user manual__2024-09-22T15:42:00.765595+00:00 [running]> on host 0bbd6d2129ab
[2024-09-22T16:26:51.422+0000] {taskinstance.py:3131} INFO - Exporting env vars: AIRFLOW_CTX_DAG_OWNER='***' AIRFLOW_CTX_DAG_ID='project' AIRFLOW_CTX_TASK_ID='store_user' AIRFLOW_CTX_EXECUTION_DATE='2024-09-22T15:42:00.765595+00:00' AIRFLOW_CTX_TRY_NUMBER='4' AIRFLOW_CTX_DAG_RUN_ID='manual__2024-09-22T15:42:00.765595+00:00'
[2024-09-22T16:26:51.423+0000] {logging_mixin.py:190} INFO - Task instance is in running state
[2024-09-22T16:26:51.423+0000] {logging_mixin.py:190} INFO -  Previous state of the Task instance: queued
[2024-09-22T16:26:51.423+0000] {logging_mixin.py:190} INFO - Current task name:store_user state:running start_date:2024-09-22 16:26:51.320437+00:00
[2024-09-22T16:26:51.423+0000] {logging_mixin.py:190} INFO - Dag name:project and current dag run status:running
[2024-09-22T16:26:51.423+0000] {taskinstance.py:731} INFO - ::endgroup::
[2024-09-22T16:26:51.424+0000] {postgres.py:191} INFO - Running copy expert: COPY users FROM stdin WITH DELIMITER as ',' , filename: /tmp/processed_user.csv
[2024-09-22T16:26:51.428+0000] {base.py:84} INFO - Retrieving connection 'postgres'
[2024-09-22T16:26:51.430+0000] {taskinstance.py:3310} ERROR - Task failed with exception
Traceback (most recent call last):
  File "/home/airflow/.local/lib/python3.12/site-packages/airflow/models/taskinstance.py", line 767, in _execute_task
    result = _execute_callable(context=context, **execute_callable_kwargs)
             ^^^^^^^^^^^^^^^^^^^^^^^^^^^^^^^^^^^^^^^^^^^^^^^^^^^^^^^^^^^^^
  File "/home/airflow/.local/lib/python3.12/site-packages/airflow/models/taskinstance.py", line 733, in _execute_callable
    return ExecutionCallableRunner(
           ^^^^^^^^^^^^^^^^^^^^^^^^
  File "/home/airflow/.local/lib/python3.12/site-packages/airflow/utils/operator_helpers.py", line 252, in run
    return self.func(*args, **kwargs)
           ^^^^^^^^^^^^^^^^^^^^^^^^^^
  File "/home/airflow/.local/lib/python3.12/site-packages/airflow/models/baseoperator.py", line 406, in wrapper
    return func(self, *args, **kwargs)
           ^^^^^^^^^^^^^^^^^^^^^^^^^^^
  File "/home/airflow/.local/lib/python3.12/site-packages/airflow/operators/python.py", line 238, in execute
    return_value = self.execute_callable()
                   ^^^^^^^^^^^^^^^^^^^^^^^
  File "/home/airflow/.local/lib/python3.12/site-packages/airflow/operators/python.py", line 256, in execute_callable
    return runner.run(*self.op_args, **self.op_kwargs)
           ^^^^^^^^^^^^^^^^^^^^^^^^^^^^^^^^^^^^^^^^^^^
  File "/home/airflow/.local/lib/python3.12/site-packages/airflow/utils/operator_helpers.py", line 252, in run
    return self.func(*args, **kwargs)
           ^^^^^^^^^^^^^^^^^^^^^^^^^^
  File "/opt/airflow/dags/project.py", line 25, in _store_user
    hook.copy_expert(
  File "/home/airflow/.local/lib/python3.12/site-packages/airflow/providers/postgres/hooks/postgres.py", line 197, in copy_expert
    cur.copy_expert(sql, file)
psycopg2.errors.BadCopyFileFormat: missing data for column "username"
CONTEXT:  COPY users, line 1: "Senta,Hochmuth,heavypanda897"

[2024-09-22T16:26:51.435+0000] {logging_mixin.py:190} INFO - Task instance in failure state
[2024-09-22T16:26:51.436+0000] {logging_mixin.py:190} INFO - Task start:2024-09-22 16:26:51.320437+00:00 end:2024-09-22 16:26:51.435670+00:00 duration:0.115233
[2024-09-22T16:26:51.436+0000] {logging_mixin.py:190} INFO - Task:<Task(PythonOperator): store_user> dag:<DAG: project> dagrun:<DagRun project @ 2024-09-22 15:42:00.765595+00:00: manual__2024-09-22T15:42:00.765595+00:00, state:running, queued_at: 2024-09-22 16:26:45.617366+00:00. externally triggered: True>
[2024-09-22T16:26:51.436+0000] {logging_mixin.py:190} INFO - Failure caused by missing data for column "username"
CONTEXT:  COPY users, line 1: "Senta,Hochmuth,heavypanda897"
[2024-09-22T16:26:51.436+0000] {taskinstance.py:1225} INFO - Marking task as FAILED. dag_id=project, task_id=store_user, run_id=manual__2024-09-22T15:42:00.765595+00:00, execution_date=20240922T154200, start_date=20240922T162651, end_date=20240922T162651
[2024-09-22T16:26:51.441+0000] {taskinstance.py:340} INFO - ::group::Post task execution logs
[2024-09-22T16:26:51.441+0000] {standard_task_runner.py:124} ERROR - Failed to execute job 78 for task store_user (missing data for column "username"
CONTEXT:  COPY users, line 1: "Senta,Hochmuth,heavypanda897"
; 8388)
Traceback (most recent call last):
  File "/home/airflow/.local/lib/python3.12/site-packages/airflow/task/task_runner/standard_task_runner.py", line 117, in _start_by_fork
    ret = args.func(args, dag=self.dag)
          ^^^^^^^^^^^^^^^^^^^^^^^^^^^^^
  File "/home/airflow/.local/lib/python3.12/site-packages/airflow/cli/cli_config.py", line 49, in command
    return func(*args, **kwargs)
           ^^^^^^^^^^^^^^^^^^^^^
  File "/home/airflow/.local/lib/python3.12/site-packages/airflow/utils/cli.py", line 115, in wrapper
    return f(*args, **kwargs)
           ^^^^^^^^^^^^^^^^^^
  File "/home/airflow/.local/lib/python3.12/site-packages/airflow/cli/commands/task_command.py", line 483, in task_run
    task_return_code = _run_task_by_selected_method(args, _dag, ti)
                       ^^^^^^^^^^^^^^^^^^^^^^^^^^^^^^^^^^^^^^^^^^^^
  File "/home/airflow/.local/lib/python3.12/site-packages/airflow/cli/commands/task_command.py", line 256, in _run_task_by_selected_method
    return _run_raw_task(args, ti)
           ^^^^^^^^^^^^^^^^^^^^^^^
  File "/home/airflow/.local/lib/python3.12/site-packages/airflow/cli/commands/task_command.py", line 341, in _run_raw_task
    return ti._run_raw_task(
           ^^^^^^^^^^^^^^^^^
  File "/home/airflow/.local/lib/python3.12/site-packages/airflow/utils/session.py", line 97, in wrapper
    return func(*args, session=session, **kwargs)
           ^^^^^^^^^^^^^^^^^^^^^^^^^^^^^^^^^^^^^^
  File "/home/airflow/.local/lib/python3.12/site-packages/airflow/models/taskinstance.py", line 3004, in _run_raw_task
    return _run_raw_task(
           ^^^^^^^^^^^^^^
  File "/home/airflow/.local/lib/python3.12/site-packages/airflow/models/taskinstance.py", line 273, in _run_raw_task
    TaskInstance._execute_task_with_callbacks(
  File "/home/airflow/.local/lib/python3.12/site-packages/airflow/models/taskinstance.py", line 3158, in _execute_task_with_callbacks
    result = self._execute_task(context, task_orig)
             ^^^^^^^^^^^^^^^^^^^^^^^^^^^^^^^^^^^^^^
  File "/home/airflow/.local/lib/python3.12/site-packages/airflow/models/taskinstance.py", line 3182, in _execute_task
    return _execute_task(self, context, task_orig)
           ^^^^^^^^^^^^^^^^^^^^^^^^^^^^^^^^^^^^^^^
  File "/home/airflow/.local/lib/python3.12/site-packages/airflow/models/taskinstance.py", line 767, in _execute_task
    result = _execute_callable(context=context, **execute_callable_kwargs)
             ^^^^^^^^^^^^^^^^^^^^^^^^^^^^^^^^^^^^^^^^^^^^^^^^^^^^^^^^^^^^^
  File "/home/airflow/.local/lib/python3.12/site-packages/airflow/models/taskinstance.py", line 733, in _execute_callable
    return ExecutionCallableRunner(
           ^^^^^^^^^^^^^^^^^^^^^^^^
  File "/home/airflow/.local/lib/python3.12/site-packages/airflow/utils/operator_helpers.py", line 252, in run
    return self.func(*args, **kwargs)
           ^^^^^^^^^^^^^^^^^^^^^^^^^^
  File "/home/airflow/.local/lib/python3.12/site-packages/airflow/models/baseoperator.py", line 406, in wrapper
    return func(self, *args, **kwargs)
           ^^^^^^^^^^^^^^^^^^^^^^^^^^^
  File "/home/airflow/.local/lib/python3.12/site-packages/airflow/operators/python.py", line 238, in execute
    return_value = self.execute_callable()
                   ^^^^^^^^^^^^^^^^^^^^^^^
  File "/home/airflow/.local/lib/python3.12/site-packages/airflow/operators/python.py", line 256, in execute_callable
    return runner.run(*self.op_args, **self.op_kwargs)
           ^^^^^^^^^^^^^^^^^^^^^^^^^^^^^^^^^^^^^^^^^^^
  File "/home/airflow/.local/lib/python3.12/site-packages/airflow/utils/operator_helpers.py", line 252, in run
    return self.func(*args, **kwargs)
           ^^^^^^^^^^^^^^^^^^^^^^^^^^
  File "/opt/airflow/dags/project.py", line 25, in _store_user
    hook.copy_expert(
  File "/home/airflow/.local/lib/python3.12/site-packages/airflow/providers/postgres/hooks/postgres.py", line 197, in copy_expert
    cur.copy_expert(sql, file)
psycopg2.errors.BadCopyFileFormat: missing data for column "username"
CONTEXT:  COPY users, line 1: "Senta,Hochmuth,heavypanda897"

[2024-09-22T16:26:51.485+0000] {local_task_job_runner.py:266} INFO - Task exited with return code 1
[2024-09-22T16:26:51.494+0000] {taskinstance.py:3900} INFO - 0 downstream tasks scheduled from follow-on schedule check
[2024-09-22T16:26:51.495+0000] {local_task_job_runner.py:245} INFO - ::endgroup::
